<mujoco model="piper">
    <compiler angle="radian" meshdir="/home/kaizhen/rl_ws/sim2real_ws/src/dcmm_sim/scripts/catch_it/assets/meshes"/>

    <size njmax="500" nconmax="100" />
    <asset>

        <!-- ground -->
        <texture type="skybox" builtin="gradient" rgb1="0.3 0.5 0.7" rgb2="0 0 0" width="512" height="3072"/>
        <texture type="2d" name="groundplane" builtin="checker" mark="edge" rgb1="0.2 0.3 0.4" rgb2="0.1 0.2 0.3"
        markrgb="0.8 0.8 0.8" width="300" height="300"/>
        <texture file="../textures/light-wood.png" name="woodplane" type="2d"/>
        <material name="groundplane" texture="woodplane" texuniform="true" texrepeat="5 5" reflectance="0.2"/>
        <mesh name="arm_base_link" file="base_link.STL" />
        <mesh name="link1" file="link1.STL" />
        <mesh name="link2" file="link2.STL" />
        <mesh name="link3" file="link3.STL" />
        <mesh name="link4" file="link4.STL" />
        <mesh name="link5" file="link5.STL" />
        <mesh name="link6" file="link6.STL" />

        <!-- <mesh name="Camera_Link" file="Camera_Link.STL" /> -->
        <mesh name="p1_Link" file="p1_Link.STL" />
        <mesh name="hand_link" file="hand_link.STL" />

          <!-- Leap Hand -->
        <mesh name="palm_lower" file="palm_lower.stl" />
        <mesh name="mcp_joint" file="mcp_joint.stl" />
        <mesh name="pip" file="pip.stl" />
        <mesh name="dip" file="dip.stl" />
        <mesh name="fingertip" file="fingertip.stl" />
        <mesh name="thumb_pip" file="thumb_pip.stl" />
        <mesh name="thumb_dip" file="thumb_dip.stl" />
        <mesh name="thumb_fingertip" file="thumb_fingertip.stl" />
    </asset>
    <worldbody>
        <light pos="0 0 10" dir="0 0 -1" directional="true" diffuse="0.7 0.7 0.7" castshadow="true"/>
        <geom name="floor" size="2 2 0.1" type="plane" friction="1 0.5 0.5" material="groundplane"/>
        <camera name="top" mode="fixed" pos="0.0 -0.125 1.3325" axisangle="1 0 0 1.2" fovy="58"/>
        <body name="arm_base">
            <geom type="mesh" contype="0" conaffinity="0" group="1" rgba="1 1 1 1" mesh="arm_base_link" />
            <!-- <geom type="mesh" rgba="0.792157 0.819608 0.933333 1" mesh="arm_base_link" /> -->
        </body>
        <body name="link1" pos="0 0 0.123">
            <inertial pos="0.000121505 0.000104632 -0.00438597" quat="0.682111 0.730899 0.0143111 -0.0175062" mass="0.71" diaginertia="0.000489262 0.000439887 0.000404551" />
            <joint name="joint1" pos="0 0 0" axis="0 0 1" limited="true" range="-2.618 2.168" actuatorfrcrange="-100 100" damping="1" frictionloss="1"/>
            <geom type="mesh" rgba="0.792157 0.819608 0.933333 1" mesh="link1" />
            <body name="link2" pos="0 0 0" quat="0.0356735 -0.0356786 -0.706207 -0.706205">
                <inertial pos="0.198666 -0.0109269 0.00142122" quat="0.510131 0.475585 0.525075 0.48773" mass="1.17" diaginertia="0.0679032 0.067745 0.00111966" />
                <joint name="joint2" pos="0 0 0" axis="0 0 1" limited="true" range="0 3.14" actuatorfrcrange="-100 100" damping="1" frictionloss="1"/>
                <geom type="mesh" rgba="0.792157 0.819608 0.933333 1" mesh="link2" />
                <body name="link3" pos="0.28503 0 0" quat="0.637536 0 0 -0.77042">
                    <inertial pos="-0.0202738 -0.133915 -0.000458683" quat="0.706282 0.705111 0.0532202 0.0339395" mass="0.5" diaginertia="0.0138227 0.0138032 0.000244685" />
                    <joint name="joint3" pos="0 0 0" axis="0 0 1" limited="true" range="-2.967 0" actuatorfrcrange="-100 100" damping="1" frictionloss="1"/>
                    <geom type="mesh" rgba="0.792157 0.819608 0.933333 1" mesh="link3" />
                    <body name="link4" pos="-0.021984 -0.25075 0" quat="0.707105 0.707108 0 0">
                        <inertial pos="-9.66636e-05 0.000876064 -0.00496881" quat="0.714689 -0.0948484 0.0635223 0.690064" mass="0.38" diaginertia="0.000191586 0.000185052 0.000152863" />
                        <joint name="joint4" pos="0 0 0" axis="0 0 1" limited="true" range="-1.745 1.745" actuatorfrcrange="-100 100" damping="1" frictionloss="1"/>
                        <geom type="mesh" rgba="0.792157 0.819608 0.933333 1" mesh="link4" />
                        <body name="link5" pos="0 0 0" quat="0.707105 -0.707108 0 0">
                            <inertial pos="-4.10554e-05 -0.0566487 -0.00372058" quat="0.709589 0.704614 0.00134613 -0.00132656" mass="0.383" diaginertia="0.00166169 0.00164328 0.000185028" />
                            <joint name="joint5" pos="0 0 0" axis="0 0 1" limited="true" range="-1.22 1.22" actuatorfrcrange="-100 100" damping="1" frictionloss="1"/>
                            <geom type="mesh" rgba="0.792157 0.819608 0.933333 1" mesh="link5" />
                            <body name="link6" pos="8.8259e-05 -0.091 0" quat="0.49999894  0.50000106  0.50000106 -0.49999894">
                                <inertial pos="-0.000182345 7.94104e-05 0.0316214" quat="0.999977 6.30554e-05 0.00678017 0.000789386" mass="0.456991" diaginertia="0.000938039 0.000723068 0.000395388" />
                                <joint name="joint6" pos="0 0 0" axis="0 0 1" limited="true" range="-2.0944 2.0944" actuatorfrcrange="-100 100" damping="1" frictionloss="1"/>
                            
                            <!-- <geom type="mesh" mesh="p1_Link" /> -->
                                <geom pos="0.0375 0.0375 0.0" axisangle="1 -1 -1 2.1" type="mesh" contype="0" conaffinity="0" group="1" mesh="p1_Link" />
                                <geom pos="0 0.045 0.0325" quat="0.500398 -0.499602 -0.5 -0.5" type="mesh" contype="0" conaffinity="0" group="1" rgba="0.2 0.2 0.2 1" mesh="hand_link" />
                                <geom pos="0 0.045 0.0325" quat="0.500398 -0.499602 -0.5 -0.5" type="mesh" rgba="0.2 0.2 0.2 1" mesh="hand_link" />
                            </body>
                        </body>
                    </body>
                </body>
            </body>
        </body>
    </worldbody>
    <actuator>
        <motor name="joint1" joint="joint1" ctrllimited="true" ctrlrange="-100 100" gear="1" />
        <motor name="joint2" joint="joint2" ctrllimited="true" ctrlrange="-100 100" gear="1" />
        <motor name="joint3" joint="joint3" ctrllimited="true" ctrlrange="-100 100" gear="1" />
        <motor name="joint4" joint="joint4" ctrllimited="true" ctrlrange="-100 100" gear="1" />
        <motor name="joint5" joint="joint5" ctrllimited="true" ctrlrange="-100 100" gear="1" />
        <motor name="joint6" joint="joint6" ctrllimited="true" ctrlrange="-100 100" gear="1" />
    </actuator>
</mujoco>
